<?xml version="1.0" ?>
<!-- =================================================================================== -->
<!-- |    This document was autogenerated by xacro from hexapod2.xacro                 | -->
<!-- |    EDITING THIS FILE BY HAND IS NOT RECOMMENDED                                 | -->
<!-- =================================================================================== -->
<robot name="hexapod">
  <material name="gray">
    <color rgba="0.6 0.6 0.6 1.0"/>
  </material>
  <material name="blue">
    <color rgba="0.2 0.4 0.9 1.0"/>
  </material>
  <material name="orange">
    <color rgba="0.9 0.5 0.1 1.0"/>
  </material>
  <link name="base_link">
    <visual>
      <geometry>
        <cylinder length="0.05" radius="0.22"/>
      </geometry>
      <material name="gray"/>
    </visual>
    <collision>
      <geometry>
        <cylinder length="0.05" radius="0.22"/>
      </geometry>
    </collision>
    <inertial>
      <origin xyz="0 0 0"/>
      <mass value="2.0"/>
      <inertia ixx="0.02" ixy="0.0" ixz="0.0" iyy="0.02" iyz="0.0" izz="0.03"/>
    </inertial>
  </link>
  <link name="leg1_hip">
    <visual>
      <geometry>
        <sphere radius="0.02"/>
      </geometry>
      <material name="blue"/>
    </visual>
    <collision>
      <geometry>
        <sphere radius="0.02"/>
      </geometry>
    </collision>
    <inertial>
      <origin xyz="0 0 0"/>
      <mass value="0.05"/>
      <inertia ixx="0.0001" ixy="0.0" ixz="0.0" iyy="0.0001" iyz="0.0" izz="0.0001"/>
    </inertial>
  </link>
  <joint name="leg1_hip_yaw" type="revolute">
    <parent link="base_link"/>
    <child link="leg1_hip"/>
    <origin rpy="0 0 0.0" xyz="0.22 0.0 -0.025"/>
    <axis xyz="0 0 1"/>
    <limit effort="10" lower="-1.57" upper="1.57" velocity="10"/>
    <dynamics damping="0.1" friction="0.05"/>
  </joint>
  <link name="leg1_thigh">
    <visual>
      <origin rpy="0 0 0" xyz="0 0 -0.075"/>
      <geometry>
        <cylinder length="0.15" radius="0.02"/>
      </geometry>
      <material name="orange"/>
    </visual>
    <collision>
      <origin rpy="0 0 0" xyz="0 0 -0.075"/>
      <geometry>
        <cylinder length="0.15" radius="0.02"/>
      </geometry>
    </collision>
    <inertial>
      <origin xyz="0 0 -0.075"/>
      <mass value="0.2"/>
      <inertia ixx="0.001" ixy="0.0" ixz="0.0" iyy="0.001" iyz="0.0" izz="0.0002"/>
    </inertial>
  </link>
  <joint name="leg1_hip_pitch" type="revolute">
    <parent link="leg1_hip"/>
    <child link="leg1_thigh"/>
    <origin rpy="0 0 0" xyz="0 0 0"/>
    <axis xyz="0 1 0"/>
    <limit effort="10" lower="-1.2" upper="1.2" velocity="10"/>
    <dynamics damping="0.1" friction="0.05"/>
  </joint>
  <link name="leg1_calf">
    <visual>
      <origin rpy="0 0 0" xyz="0 0 -0.075"/>
      <geometry>
        <cylinder length="0.15" radius="0.018000000000000002"/>
      </geometry>
      <material name="blue"/>
    </visual>
    <collision>
      <origin rpy="0 0 0" xyz="0 0 -0.075"/>
      <geometry>
        <cylinder length="0.15" radius="0.018000000000000002"/>
      </geometry>
    </collision>
    <inertial>
      <origin xyz="0 0 -0.075"/>
      <mass value="0.15"/>
      <inertia ixx="0.0008" ixy="0.0" ixz="0.0" iyy="0.0008" iyz="0.0" izz="0.00015"/>
    </inertial>
  </link>
  <joint name="leg1_knee" type="revolute">
    <parent link="leg1_thigh"/>
    <child link="leg1_calf"/>
    <origin rpy="0 0 0" xyz="0 0 -0.15"/>
    <axis xyz="0 1 0"/>
    <limit effort="10" lower="-2.0" upper="0.0" velocity="10"/>
    <dynamics damping="0.1" friction="0.05"/>
  </joint>
  <link name="leg2_hip">
    <visual>
      <geometry>
        <sphere radius="0.02"/>
      </geometry>
      <material name="blue"/>
    </visual>
    <collision>
      <geometry>
        <sphere radius="0.02"/>
      </geometry>
    </collision>
    <inertial>
      <origin xyz="0 0 0"/>
      <mass value="0.05"/>
      <inertia ixx="0.0001" ixy="0.0" ixz="0.0" iyy="0.0001" iyz="0.0" izz="0.0001"/>
    </inertial>
  </link>
  <joint name="leg2_hip_yaw" type="revolute">
    <parent link="base_link"/>
    <child link="leg2_hip"/>
    <origin rpy="0 0 1.0472" xyz="0.11 0.190525588 -0.025"/>
    <axis xyz="0 0 1"/>
    <limit effort="10" lower="-1.57" upper="1.57" velocity="10"/>
    <dynamics damping="0.1" friction="0.05"/>
  </joint>
  <link name="leg2_thigh">
    <visual>
      <origin rpy="0 0 0" xyz="0 0 -0.075"/>
      <geometry>
        <cylinder length="0.15" radius="0.02"/>
      </geometry>
      <material name="orange"/>
    </visual>
    <collision>
      <origin rpy="0 0 0" xyz="0 0 -0.075"/>
      <geometry>
        <cylinder length="0.15" radius="0.02"/>
      </geometry>
    </collision>
    <inertial>
      <origin xyz="0 0 -0.075"/>
      <mass value="0.2"/>
      <inertia ixx="0.001" ixy="0.0" ixz="0.0" iyy="0.001" iyz="0.0" izz="0.0002"/>
    </inertial>
  </link>
  <joint name="leg2_hip_pitch" type="revolute">
    <parent link="leg2_hip"/>
    <child link="leg2_thigh"/>
    <origin rpy="0 0 0" xyz="0 0 0"/>
    <axis xyz="0 1 0"/>
    <limit effort="10" lower="-1.2" upper="1.2" velocity="10"/>
    <dynamics damping="0.1" friction="0.05"/>
  </joint>
  <link name="leg2_calf">
    <visual>
      <origin rpy="0 0 0" xyz="0 0 -0.075"/>
      <geometry>
        <cylinder length="0.15" radius="0.018000000000000002"/>
      </geometry>
      <material name="blue"/>
    </visual>
    <collision>
      <origin rpy="0 0 0" xyz="0 0 -0.075"/>
      <geometry>
        <cylinder length="0.15" radius="0.018000000000000002"/>
      </geometry>
    </collision>
    <inertial>
      <origin xyz="0 0 -0.075"/>
      <mass value="0.15"/>
      <inertia ixx="0.0008" ixy="0.0" ixz="0.0" iyy="0.0008" iyz="0.0" izz="0.00015"/>
    </inertial>
  </link>
  <joint name="leg2_knee" type="revolute">
    <parent link="leg2_thigh"/>
    <child link="leg2_calf"/>
    <origin rpy="0 0 0" xyz="0 0 -0.15"/>
    <axis xyz="0 1 0"/>
    <limit effort="10" lower="-2.0" upper="0.0" velocity="10"/>
    <dynamics damping="0.1" friction="0.05"/>
  </joint>
  <link name="leg3_hip">
    <visual>
      <geometry>
        <sphere radius="0.02"/>
      </geometry>
      <material name="blue"/>
    </visual>
    <collision>
      <geometry>
        <sphere radius="0.02"/>
      </geometry>
    </collision>
    <inertial>
      <origin xyz="0 0 0"/>
      <mass value="0.05"/>
      <inertia ixx="0.0001" ixy="0.0" ixz="0.0" iyy="0.0001" iyz="0.0" izz="0.0001"/>
    </inertial>
  </link>
  <joint name="leg3_hip_yaw" type="revolute">
    <parent link="base_link"/>
    <child link="leg3_hip"/>
    <origin rpy="0 0 2.0944" xyz="-0.11 0.190525588 -0.025"/>
    <axis xyz="0 0 1"/>
    <limit effort="10" lower="-1.57" upper="1.57" velocity="10"/>
    <dynamics damping="0.1" friction="0.05"/>
  </joint>
  <link name="leg3_thigh">
    <visual>
      <origin rpy="0 0 0" xyz="0 0 -0.075"/>
      <geometry>
        <cylinder length="0.15" radius="0.02"/>
      </geometry>
      <material name="orange"/>
    </visual>
    <collision>
      <origin rpy="0 0 0" xyz="0 0 -0.075"/>
      <geometry>
        <cylinder length="0.15" radius="0.02"/>
      </geometry>
    </collision>
    <inertial>
      <origin xyz="0 0 -0.075"/>
      <mass value="0.2"/>
      <inertia ixx="0.001" ixy="0.0" ixz="0.0" iyy="0.001" iyz="0.0" izz="0.0002"/>
    </inertial>
  </link>
  <joint name="leg3_hip_pitch" type="revolute">
    <parent link="leg3_hip"/>
    <child link="leg3_thigh"/>
    <origin rpy="0 0 0" xyz="0 0 0"/>
    <axis xyz="0 1 0"/>
    <limit effort="10" lower="-1.2" upper="1.2" velocity="10"/>
    <dynamics damping="0.1" friction="0.05"/>
  </joint>
  <link name="leg3_calf">
    <visual>
      <origin rpy="0 0 0" xyz="0 0 -0.075"/>
      <geometry>
        <cylinder length="0.15" radius="0.018000000000000002"/>
      </geometry>
      <material name="blue"/>
    </visual>
    <collision>
      <origin rpy="0 0 0" xyz="0 0 -0.075"/>
      <geometry>
        <cylinder length="0.15" radius="0.018000000000000002"/>
      </geometry>
    </collision>
    <inertial>
      <origin xyz="0 0 -0.075"/>
      <mass value="0.15"/>
      <inertia ixx="0.0008" ixy="0.0" ixz="0.0" iyy="0.0008" iyz="0.0" izz="0.00015"/>
    </inertial>
  </link>
  <joint name="leg3_knee" type="revolute">
    <parent link="leg3_thigh"/>
    <child link="leg3_calf"/>
    <origin rpy="0 0 0" xyz="0 0 -0.15"/>
    <axis xyz="0 1 0"/>
    <limit effort="10" lower="-2.0" upper="0.0" velocity="10"/>
    <dynamics damping="0.1" friction="0.05"/>
  </joint>
  <link name="leg4_hip">
    <visual>
      <geometry>
        <sphere radius="0.02"/>
      </geometry>
      <material name="blue"/>
    </visual>
    <collision>
      <geometry>
        <sphere radius="0.02"/>
      </geometry>
    </collision>
    <inertial>
      <origin xyz="0 0 0"/>
      <mass value="0.05"/>
      <inertia ixx="0.0001" ixy="0.0" ixz="0.0" iyy="0.0001" iyz="0.0" izz="0.0001"/>
    </inertial>
  </link>
  <joint name="leg4_hip_yaw" type="revolute">
    <parent link="base_link"/>
    <child link="leg4_hip"/>
    <origin rpy="0 0 3.1416" xyz="-0.22 0.0 -0.025"/>
    <axis xyz="0 0 1"/>
    <limit effort="10" lower="-1.57" upper="1.57" velocity="10"/>
    <dynamics damping="0.1" friction="0.05"/>
  </joint>
  <link name="leg4_thigh">
    <visual>
      <origin rpy="0 0 0" xyz="0 0 -0.075"/>
      <geometry>
        <cylinder length="0.15" radius="0.02"/>
      </geometry>
      <material name="orange"/>
    </visual>
    <collision>
      <origin rpy="0 0 0" xyz="0 0 -0.075"/>
      <geometry>
        <cylinder length="0.15" radius="0.02"/>
      </geometry>
    </collision>
    <inertial>
      <origin xyz="0 0 -0.075"/>
      <mass value="0.2"/>
      <inertia ixx="0.001" ixy="0.0" ixz="0.0" iyy="0.001" iyz="0.0" izz="0.0002"/>
    </inertial>
  </link>
  <joint name="leg4_hip_pitch" type="revolute">
    <parent link="leg4_hip"/>
    <child link="leg4_thigh"/>
    <origin rpy="0 0 0" xyz="0 0 0"/>
    <axis xyz="0 1 0"/>
    <limit effort="10" lower="-1.2" upper="1.2" velocity="10"/>
    <dynamics damping="0.1" friction="0.05"/>
  </joint>
  <link name="leg4_calf">
    <visual>
      <origin rpy="0 0 0" xyz="0 0 -0.075"/>
      <geometry>
        <cylinder length="0.15" radius="0.018000000000000002"/>
      </geometry>
      <material name="blue"/>
    </visual>
    <collision>
      <origin rpy="0 0 0" xyz="0 0 -0.075"/>
      <geometry>
        <cylinder length="0.15" radius="0.018000000000000002"/>
      </geometry>
    </collision>
    <inertial>
      <origin xyz="0 0 -0.075"/>
      <mass value="0.15"/>
      <inertia ixx="0.0008" ixy="0.0" ixz="0.0" iyy="0.0008" iyz="0.0" izz="0.00015"/>
    </inertial>
  </link>
  <joint name="leg4_knee" type="revolute">
    <parent link="leg4_thigh"/>
    <child link="leg4_calf"/>
    <origin rpy="0 0 0" xyz="0 0 -0.15"/>
    <axis xyz="0 1 0"/>
    <limit effort="10" lower="-2.0" upper="0.0" velocity="10"/>
    <dynamics damping="0.1" friction="0.05"/>
  </joint>
  <link name="leg5_hip">
    <visual>
      <geometry>
        <sphere radius="0.02"/>
      </geometry>
      <material name="blue"/>
    </visual>
    <collision>
      <geometry>
        <sphere radius="0.02"/>
      </geometry>
    </collision>
    <inertial>
      <origin xyz="0 0 0"/>
      <mass value="0.05"/>
      <inertia ixx="0.0001" ixy="0.0" ixz="0.0" iyy="0.0001" iyz="0.0" izz="0.0001"/>
    </inertial>
  </link>
  <joint name="leg5_hip_yaw" type="revolute">
    <parent link="base_link"/>
    <child link="leg5_hip"/>
    <origin rpy="0 0 -2.0944" xyz="-0.11 -0.190525588 -0.025"/>
    <axis xyz="0 0 1"/>
    <limit effort="10" lower="-1.57" upper="1.57" velocity="10"/>
    <dynamics damping="0.1" friction="0.05"/>
  </joint>
  <link name="leg5_thigh">
    <visual>
      <origin rpy="0 0 0" xyz="0 0 -0.075"/>
      <geometry>
        <cylinder length="0.15" radius="0.02"/>
      </geometry>
      <material name="orange"/>
    </visual>
    <collision>
      <origin rpy="0 0 0" xyz="0 0 -0.075"/>
      <geometry>
        <cylinder length="0.15" radius="0.02"/>
      </geometry>
    </collision>
    <inertial>
      <origin xyz="0 0 -0.075"/>
      <mass value="0.2"/>
      <inertia ixx="0.001" ixy="0.0" ixz="0.0" iyy="0.001" iyz="0.0" izz="0.0002"/>
    </inertial>
  </link>
  <joint name="leg5_hip_pitch" type="revolute">
    <parent link="leg5_hip"/>
    <child link="leg5_thigh"/>
    <origin rpy="0 0 0" xyz="0 0 0"/>
    <axis xyz="0 1 0"/>
    <limit effort="10" lower="-1.2" upper="1.2" velocity="10"/>
    <dynamics damping="0.1" friction="0.05"/>
  </joint>
  <link name="leg5_calf">
    <visual>
      <origin rpy="0 0 0" xyz="0 0 -0.075"/>
      <geometry>
        <cylinder length="0.15" radius="0.018000000000000002"/>
      </geometry>
      <material name="blue"/>
    </visual>
    <collision>
      <origin rpy="0 0 0" xyz="0 0 -0.075"/>
      <geometry>
        <cylinder length="0.15" radius="0.018000000000000002"/>
      </geometry>
    </collision>
    <inertial>
      <origin xyz="0 0 -0.075"/>
      <mass value="0.15"/>
      <inertia ixx="0.0008" ixy="0.0" ixz="0.0" iyy="0.0008" iyz="0.0" izz="0.00015"/>
    </inertial>
  </link>
  <joint name="leg5_knee" type="revolute">
    <parent link="leg5_thigh"/>
    <child link="leg5_calf"/>
    <origin rpy="0 0 0" xyz="0 0 -0.15"/>
    <axis xyz="0 1 0"/>
    <limit effort="10" lower="-2.0" upper="0.0" velocity="10"/>
    <dynamics damping="0.1" friction="0.05"/>
  </joint>
  <link name="leg6_hip">
    <visual>
      <geometry>
        <sphere radius="0.02"/>
      </geometry>
      <material name="blue"/>
    </visual>
    <collision>
      <geometry>
        <sphere radius="0.02"/>
      </geometry>
    </collision>
    <inertial>
      <origin xyz="0 0 0"/>
      <mass value="0.05"/>
      <inertia ixx="0.0001" ixy="0.0" ixz="0.0" iyy="0.0001" iyz="0.0" izz="0.0001"/>
    </inertial>
  </link>
  <joint name="leg6_hip_yaw" type="revolute">
    <parent link="base_link"/>
    <child link="leg6_hip"/>
    <origin rpy="0 0 -1.0472" xyz="0.11 -0.190525588 -0.025"/>
    <axis xyz="0 0 1"/>
    <limit effort="10" lower="-1.57" upper="1.57" velocity="10"/>
    <dynamics damping="0.1" friction="0.05"/>
  </joint>
  <link name="leg6_thigh">
    <visual>
      <origin rpy="0 0 0" xyz="0 0 -0.075"/>
      <geometry>
        <cylinder length="0.15" radius="0.02"/>
      </geometry>
      <material name="orange"/>
    </visual>
    <collision>
      <origin rpy="0 0 0" xyz="0 0 -0.075"/>
      <geometry>
        <cylinder length="0.15" radius="0.02"/>
      </geometry>
    </collision>
    <inertial>
      <origin xyz="0 0 -0.075"/>
      <mass value="0.2"/>
      <inertia ixx="0.001" ixy="0.0" ixz="0.0" iyy="0.001" iyz="0.0" izz="0.0002"/>
    </inertial>
  </link>
  <joint name="leg6_hip_pitch" type="revolute">
    <parent link="leg6_hip"/>
    <child link="leg6_thigh"/>
    <origin rpy="0 0 0" xyz="0 0 0"/>
    <axis xyz="0 1 0"/>
    <limit effort="10" lower="-1.2" upper="1.2" velocity="10"/>
    <dynamics damping="0.1" friction="0.05"/>
  </joint>
  <link name="leg6_calf">
    <visual>
      <origin rpy="0 0 0" xyz="0 0 -0.075"/>
      <geometry>
        <cylinder length="0.15" radius="0.018000000000000002"/>
      </geometry>
      <material name="blue"/>
    </visual>
    <collision>
      <origin rpy="0 0 0" xyz="0 0 -0.075"/>
      <geometry>
        <cylinder length="0.15" radius="0.018000000000000002"/>
      </geometry>
    </collision>
    <inertial>
      <origin xyz="0 0 -0.075"/>
      <mass value="0.15"/>
      <inertia ixx="0.0008" ixy="0.0" ixz="0.0" iyy="0.0008" iyz="0.0" izz="0.00015"/>
    </inertial>
  </link>
  <joint name="leg6_knee" type="revolute">
    <parent link="leg6_thigh"/>
    <child link="leg6_calf"/>
    <origin rpy="0 0 0" xyz="0 0 -0.15"/>
    <axis xyz="0 1 0"/>
    <limit effort="10" lower="-2.0" upper="0.0" velocity="10"/>
    <dynamics damping="0.1" friction="0.05"/>
  </joint>
</robot>

